#!/usr/bin/env python3

def print_fix_summary():
    print("ðŸŽ‰ SAGEMAKER VPC ENDPOINT FIX COMPLETED")
    print("=" * 50)
    
    print("\nâœ… WHAT WAS FIXED:")
    print("â€¢ Created SageMaker API VPC Endpoint: vpce-040a072980491a0c8")
    print("â€¢ Service: com.amazonaws.us-west-2.sagemaker.api")
    print("â€¢ Status: Available")
    
    print("\nâœ… CONNECTIVITY STATUS:")
    print("â€¢ SageMaker API VPCE: âœ“ Present")
    print("â€¢ ECR API VPCE: âœ“ Present") 
    print("â€¢ ECR Docker VPCE: âœ“ Present")
    
    print("\nðŸ”§ NEXT STEPS:")
    print("1. Restart JupyterLab applications in affected spaces:")
    print("   - f1 space (where the error occurred)")
    print("   - f2 space")
    print("   - test space")
    print("\n2. The timeout error should be resolved:")
    print("   'Connect timeout on endpoint URL: https://api.sagemaker.us-west-2.amazonaws.com/'")
    
    print("\nðŸ“‹ VERIFICATION:")
    print("â€¢ Check JupyterLab logs for absence of timeout errors")
    print("â€¢ SageMaker service calls should now work properly")
    print("â€¢ All spaces can now communicate with SageMaker APIs")

if __name__ == "__main__":
    print_fix_summary()